Workbook

Sheet Guide
A1: Submission 2 - Test Case Design Sheet
A2: Playwright QA Automation for Insurance Order Entry Platform
A4: Purpose | B4: Converts the Submission 1 QA plan into detailed, traceable test cases for the Playwright automation build.
A5: Sheets | B5: Test Cases (the design sheet) | Coverage Summary | Risk Traceability | Validation ID Matrix | Test Data | Open Items | Review Log (v2 reviewer findings)
A6: Version | B6: v2 - reviewed against all Submission 2 documents; 32 cases and 3 columns added, 8 cases rewritten. See Review Log.
A7: Columns follow | B7: Guideline section 5: ID/title, module and requirement/risk/defect link, preconditions, steps, expected result, severity/priority, evidence required, automation status.
A8: Build Wave | B8: 1 = smoke path and critical checks to automate first | 2 = core validations | 3 = extended coverage. The 'Short-Cohort Set' column (Y) marks the 30-35 test fallback.
A9: Seeded defect links | B9: The seeded defect catalog was not supplied. Column G holds the defect class described in the problem statement; replace with catalog codes once available.
A10: Placeholders | B10: 'CONFIRM' marks values (limits, formats, counts) that must be verified in the running app. See Open Items.
A11: Automation Status | B11: All cases start as 'Not started'. Update as specs are written (Automated / In progress / Blocked).
A12: Extra columns | B12: Scenario Type (Positive/Negative/Boundary), Backend Cross-check (API/DB), Isolation / Cleanup (independence and shared-state notes).
A13: Editable cells | B13: Yellow cells on Open Items, and the Automation Status / Execution Result / Notes columns on Test Cases.
A15: Snapshot
A16: Total test cases | B16: =COUNTA('Test Cases'!A2:A174)
A17: Critical severity | B17: =COUNTIF('Test Cases'!L2:L174,"Critical")
A18: P1 priority | B18: =COUNTIF('Test Cases'!M2:M174,"P1")
A19: Wave 1 (smoke) | B19: =COUNTIF('Test Cases'!N2:N174,1)
A20: Validation IDs covered | B20: =COUNTIF('Validation ID Matrix'!E4:E72,"Covered")&" of "&COUNTA('Validation ID Matrix'!A4:A72)
A21: Open items | B21: =COUNTIF('Open Items'!F4:F40,"Open")

Sheet Test Cases
A1: Test Case ID | B1: Title | C1: Module | D1: Test Type | E1: Requirement / Validation ID | F1: Risk ID (Sub 1) | G1: Seeded Defect / Risk Link | H1: Preconditions | I1: Test Steps | J1: Test Data | K1: Expected Result | L1: Severity | M1: Priority | N1: Build Wave | O1: Tags | P1: Evidence Required | Q1: Automation Status | R1: Planned Spec File | S1: Execution Result | T1: Notes / Confirm | U1: Short-Cohort Set | V1: Scenario Type | W1: Backend Cross-check (API/DB) | X1: Isolation / Cleanup
A2: TC-AUTH-01 | B2: Valid agent logs in and lands on dashboard | C2: Authentication | D2: UI | E2: AUTH-V01 | F2: QR-01 | G2: Valid agent cannot log in after auth change | H2: App reachable; valid agent seeded; no active session. | I2: 1. Open /login. 2. Enter valid username and password. 3. Click Sign in. | J2: VALID_AGENT credentials from .env | K2: Redirected to /dashboard; URL ends with /dashboard; agent greeting/name visible; no error message. | L2: Critical | M2: P1 | N2: 1 | O2: @smoke @regression auth | P2: Screenshot of dashboard; trace on retry | Q2: Automated | R2: tests/auth/login.spec.ts | S2: Not run | U2: Y | V2: Positive | W2: API: POST /api/auth/login returns 200 + token/session | X2: Creates its own application via fixture (independent; unique generated data).
A3: TC-AUTH-02 | B3: Invalid password and unknown user show the same safe error and no session | C3: Authentication | D3: UI | E3: AUTH-V02 | F3: QR-01 | G3: Misleading login error message | H3: Valid agent exists; no session. | I3: 1. Open /login. 2. Enter valid username with wrong password; submit. 3. Enter an unknown username with any password; submit. 4. Try opening /dashboard. | J3: VALID_AGENT username + 'Wrong#Pass1'; 'no.such.user' + 'Wrong#Pass1' | K3: Stays on /login; invalid-credentials message visible (not 'account locked'); /dashboard still redirects to /login. | L3: High | M3: P1 | N3: 2 | O3: @regression auth | P3: Screenshot of error message | Q3: Automated | R3: tests/auth/login.spec.ts | S3: Not run | U3: N | V3: Negative | W3: - | X3: Creates its own application via fixture (independent; unique generated data).
A4: TC-AUTH-03 | B4: Blank username and password show mandatory-field errors | C4: Authentication | D4: UI | E4: AUTH-V03 | F4: QR-01 | G4: Mandatory login validation missing | H4: On /login with empty form. | I4: 1. Leave username and password empty. 2. Click Sign in. | J4: Empty values | K4: Field-level required errors on both fields; no request treated as successful; stays on /login. | L4: Medium | M4: P2 | N4: 2 | O4: @regression auth | P4: Screenshot of field errors | Q4: Automated | R4: tests/auth/login.spec.ts | S4: Not run | U4: N | V4: Negative | W4: - | X4: Creates its own application via fixture (independent; unique generated data).
A5: TC-AUTH-04 | B5: Logout clears session and protected routes redirect | C5: Authentication | D5: UI | E5: AUTH-V04 | F5: QR-01 | G5: No logout session clearing | H5: Logged in as valid agent. | I5: 1. Click Logout. 2. Confirm redirect to /login. 3. Use browser Back. 4. Open /dashboard directly. | J5: VALID_AGENT | K5: Redirected to /login after logout; Back and direct /dashboard access redirect to /login; session cookie/token cleared. | L5: Critical | M5: P1 | N5: 1 | O5: @smoke @regression auth | P5: Screenshot + cookie state note | Q5: Automated | R5: tests/auth/session.spec.ts | S5: Not run | U5: Y | V5: Positive | W5: API: GET /api/applications returns 401 after logout | X5: Creates its own application via fixture (independent; unique generated data).
A6: TC-AUTH-05 | B6: Direct access to protected routes without login is blocked | C6: Authentication | D6: UI | E6: AUTH-V05 | F6: QR-01 | G6: Dashboard reachable without login | H6: Fresh browser context, no cookies. | I6: 1. Open /dashboard in a fresh context. 2. Open /applications/new. 3. Open /applications/<id>/review. | J6: Seeded application id | K6: Each URL redirects to /login; no dashboard or application data is rendered. | L6: Critical | M6: P1 | N6: 1 | O6: @smoke @regression auth | P6: Screenshot; URL assertion in trace | Q6: Automated | R6: tests/auth/session.spec.ts | S6: Not run | U6: Y | V6: Negative | W6: - | X6: Creates its own application via fixture (independent; unique generated data).
A7: TC-AUTH-06 | B7: Locked user cannot access dashboard and sees accurate message | C7: Authentication | D7: UI | E7: AUTH-V06 | F7: QR-01 | G7: Misleading locked message | H7: Locked agent seeded. | I7: 1. Open /login. 2. Enter locked agent credentials. 3. Click Sign in. 4. Open /dashboard. | J7: LOCKED_AGENT credentials | K7: Account-locked message shown (accurate wording); no session created; /dashboard redirects to /login. | L7: High | M7: P1 | N7: 2 | O7: @regression auth | P7: Screenshot of locked message | Q7: Automated | R7: tests/auth/lockout.spec.ts | S7: Not run | U7: N | V7: Negative | W7: - | X7: Read-only: uses seeded locked agent.
A8: TC-AUTH-07 | B8: Account locks after five failed login attempts | C8: Authentication | D8: UI | E8: AUTH-V07 | F8: QR-01 | G8: Lockout not enforced at 5 attempts | H8: Dedicated non-locked test agent reserved for this test (lock state persists). | I8: 1. Submit wrong password 4 times; confirm normal invalid message each time. 2. Submit wrong password a 5th time. 3. Submit the CORRECT password. | J8: LOCKOUT_TEST_AGENT + wrong password | K8: After the 5th failure the account is locked; correct password is then rejected with locked message. Lock is NOT triggered on attempt 4. | L8: High | M8: P1 | N8: 2 | O8: @regression auth | P8: Screenshots after attempt 4, 5 and correct-password try | Q8: Automated | R8: tests/auth/lockout.spec.ts | S8: Not run | U8: Y | V8: Boundary | W8: DB (if approved): failed_attempts / locked flag | X8: Reserved LOCKOUT_TEST_AGENT; needs manual/admin unlock after run - run serially (workers=1 for this file).
A9: TC-AUTH-08 | B9: Weak password rejected during reset/change | C9: Authentication | D9: UI | E9: AUTH-V08 | F9: QR-01 | G9: Weak password accepted | H9: Reset/change password reachable (/forgot-password or profile). | I9: 1. Start reset for a test agent. 2. Enter new password from weak set (short, no digit, no special, common word). 3. Submit. | J9: 'abc', 'password', '12345678', 'Abcdefgh' | K9: Each weak value rejected with a clear policy message; password not changed (old password still works). | L9: High | M9: P1 | N9: 2 | O9: @regression auth | P9: Screenshot per weak value | Q9: Automated | R9: tests/auth/password.spec.ts | S9: Not run | U9: N | V9: Negative | W9: - | X9: Disposable agent; no password change persists on rejection.
A10: TC-AUTH-09 | B10: MFA agent completes login with simulated OTP | C10: Authentication | D10: UI | E10: Guideline: reset OTP / MFA | F10: QR-01 | G10: MFA/OTP bypass or wrong-code acceptance | H10: MFA agent seeded; OTP value known/simulated. | I10: 1. Login as MFA agent. 2. Enter wrong OTP, observe error. 3. Enter correct OTP. | J10: MFA_AGENT, OTP from .env (CONFIRM) | K10: Wrong OTP rejected; correct OTP reaches /dashboard. | L10: High | M10: P2 | N10: 3 | O10: @regression auth | P10: Screenshots of OTP error and dashboard | Q10: Automated | R10: tests/auth/mfa.spec.ts | S10: Not run | T10: Exact value/rule to be confirmed from app (see Open Items). | U10: N | V10: Positive | W10: - | X10: Creates its own application via fixture (independent; unique generated data).
A11: TC-AUTH-10 | B11: Password reset via OTP succeeds with valid new password | C11: Authentication | D11: UI | E11: Guideline: reset OTP | F11: QR-01 | G11: Reset OTP flow broken | H11: Disposable test agent; /forgot-password available. | I11: 1. Open /forgot-password; enter username/email. 2. Enter simulated OTP. 3. Set compliant new password. 4. Login with new password. | J11: Reset test agent; strong password | K11: Reset completes; login with new password succeeds; old password no longer works. | L11: Medium | M11: P3 | N11: 3 | O11: @regression auth | P11: Screenshots of each step | Q11: Automated | R11: tests/auth/password.spec.ts | S11: Not run | U11: N | V11: Positive | W11: - | X11: Disposable reset agent; password restored in afterEach.
A12: TC-AUTH-11 | B12: Reusing the same password on reset is rejected | C12: Authentication | D12: UI | E12: Guideline: same password reuse | F12: QR-01 | G12: Same-password reuse allowed | H12: Disposable test agent with known current password. | I12: 1. Start password reset/change. 2. Enter new password identical to current password. 3. Submit. | J12: Current password | K12: Request rejected with a 'cannot reuse' message; password unchanged. | L12: Medium | M12: P3 | N12: 3 | O12: @regression auth | P12: Screenshot of rejection | Q12: Automated | R12: tests/auth/password.spec.ts | S12: Not run | U12: N | V12: Negative | W12: - | X12: Disposable reset agent; password restored in afterEach.
A13: TC-AUTH-12 | B13: Expired/timed-out session forces re-login without data exposure | C13: Authentication | D13: UI | E13: Spec: session timeout / Sub 1 path 'Session expiration' | F13: QR-01, QR-10 | G13: Session not invalidated on timeout | H13: Logged in; session lifetime known (CONFIRM) or session cookie can be cleared/expired in the test. | I13: 1. Login and open an application step with unsaved edits. 2. Expire the session (wait for timeout or delete/expire the session cookie via context). 3. Click Save or navigate to another step. 4. Re-login. | J13: VALID_AGENT | K13: User is redirected to /login; no protected data rendered; API calls return 401; after re-login the previously SAVED data is intact and unsaved edits are not silently stored. | L13: High | M13: P2 | N13: 3 | O13: @regression auth | P13: Screenshot of redirect; network log showing 401 | Q13: Automated | R13: tests/auth/session.spec.ts | S13: Not run | T13: Exact value/rule to be confirmed from app (see Open Items). | U13: N | V13: Negative | W13: - | X13: Creates its own application via fixture (independent; unique generated data).
A14: TC-AUTH-13 | B14: Pending (unapproved) agent cannot access the platform | C14: Authentication | D14: UI | E14: Spec: user type 'pending agent' | F14: QR-01 | G14: Unapproved account gains access | H14: Pending agent seeded. | I14: 1. Login with pending agent credentials. 2. Open /dashboard. | J14: PENDING_AGENT | K14: Access is denied with an accurate pending-approval message (behavior CONFIRM); no session granted; /dashboard redirects to /login. | L14: High | M14: P2 | N14: 3 | O14: @regression auth | P14: Screenshot of message | Q14: Automated | R14: tests/auth/login.spec.ts | S14: Not run | T14: Exact value/rule to be confirmed from app (see Open Items). | U14: N | V14: Negative | W14: - | X14: Creates its own application via fixture (independent; unique generated data).
A15: TC-DASH-01 | B15: Dashboard shows summaries and New Application CTA after login | C15: Dashboard | D15: UI | E15: DASH-V01 | F15: QR-02 | G15: Dashboard summary missing/incorrect | H15: Logged in as valid agent with seeded applications. | I15: 1. Login as valid agent. 2. Observe dashboard. | J15: VALID_AGENT | K15: Draft summary, submitted summary and 'New application' CTA are visible. | L15: High | M15: P1 | N15: 1 | O15: @smoke @regression dashboard | P15: Screenshot of dashboard | Q15: Automated | R15: tests/dashboard/dashboard.spec.ts | S15: Not run | U15: Y | V15: Positive | W15: - | X15: Creates its own application via fixture (independent; unique generated data).
A16: TC-DASH-02 | B16: Agent sees only own applications (UI isolation) | C16: Dashboard | D16: UI | E16: DASH-V02 | F16: QR-02 | G16: Agent sees other agents' applications | H16: Two valid agents each with distinct seeded applications. | I16: 1. Login as agent A; record application IDs. 2. Logout; login as agent B; record IDs. 3. Compare lists. | J16: VALID_AGENT, SECOND_AGENT | K16: The two ID sets do not overlap; neither agent sees the other's applications. | L16: Critical | M16: P1 | N16: 2 | O16: @regression dashboard | P16: Screenshots of both lists | Q16: Automated | R16: tests/dashboard/dashboard.spec.ts | S16: Not run | U16: Y | V16: Negative | W16: - | X16: Read-only seeded applications of two agents.
A17: TC-DASH-03 | B17: New agent sees empty-state message and CTA | C17: Dashboard | D17: UI | E17: DASH-V03 | F17: QR-02 | G17: Empty state not handled | H17: New agent with zero applications. | I17: 1. Login as new agent. | J17: NEW_AGENT | K17: Empty-state copy shown; CTA to start a new application visible; no rows rendered. | L17: Low | M17: P3 | N17: 3 | O17: @regression dashboard | P17: Screenshot of empty state | Q17: Automated | R17: tests/dashboard/dashboard.spec.ts | S17: Not run | U17: N | V17: Positive | W17: - | X17: Read-only: new agent has no applications.
A18: TC-DASH-04 | B18: Draft can be resumed with previously entered data | C18: Dashboard | D18: UI | E18: DASH-V04 | F18: QR-02, QR-10 | G18: Draft not resumable / not persisted | H18: Seeded draft application owned by valid agent (or created in test). | I18: 1. From dashboard open the draft row. 2. Inspect the step and field values. | J18: Seeded draft id | K18: Application opens at the saved step; previously saved values are present and unchanged. | L18: High | M18: P1 | N18: 2 | O18: @regression dashboard | P18: Screenshot of restored values | Q18: Automated | R18: tests/dashboard/dashboard.spec.ts | S18: Not run | U18: N | V18: Positive | W18: API/DB: saved draft values | X18: Read-only seeded draft (or draft created by fixture).
A19: TC-DASH-05 | B19: Status filter returns correct rows (Draft/Submitted/Approved) | C19: Dashboard | D19: UI | E19: DASH-V05 | F19: QR-02 | G19: Filters return wrong rows | H19: Seeded draft, submitted and approved applications. | I19: 1. Apply Draft filter; read rows. 2. Apply Submitted filter. 3. Apply Approved filter. | J19: Seeded applications of each status | K19: Each filter shows only rows of that status; counts match seed data. | L19: Medium | M19: P2 | N19: 2 | O19: @regression dashboard | P19: Screenshot per filter | Q19: Automated | R19: tests/dashboard/dashboard.spec.ts | S19: Not run | U19: N | V19: Positive | W19: - | X19: Read-only seeded applications of each status.
A20: TC-DASH-06 | B20: Dashboard status matches status API for each application (status endpoint) | C20: Dashboard | D20: UI | E20: DASH-V06 | F20: QR-02, QR-09 | G20: Dashboard status differs from backend | H20: Valid agent logged in; session available to request context. | I20: 1. Read each dashboard row id + status. 2. Call GET /api/applications/{id}/status for each. 3. Compare. | J20: Seeded applications | K20: Every UI status equals API status. | L20: High | M20: P1 | N20: 2 | O20: @regression dashboard @api | P20: Table of UI vs API values in test log | Q20: Automated | R20: tests/dashboard/dashboard-api.spec.ts | S20: Not run | U20: N | V20: Positive | W20: API: GET /api/applications/{id}/status | X20: Creates its own application via fixture (independent; unique generated data).
A21: TC-DASH-07 | B21: Dashboard search finds an application by name/reference | C21: Dashboard | D21: UI | E21: Spec: dashboard search | F21: QR-02 | G21: Search returns wrong rows | H21: Seeded applications with distinct client names/references. | I21: 1. Search by a known client name. 2. Search by a known reference/ID. 3. Search for a non-existent term. 4. Clear search. | J21: Seeded names/references | K21: Matching rows only for 1 and 2; empty-result message for 3; full list restored after 4. | L21: Medium | M21: P2 | N21: 3 | O21: @regression dashboard | P21: Screenshots of each result state | Q21: Automated | R21: tests/dashboard/dashboard.spec.ts | S21: Not run | U21: N | V21: Positive | W21: - | X21: Creates its own application via fixture (independent; unique generated data).
A22: TC-DASH-08 | B22: Agent cannot open another agent's application by direct URL | C22: Dashboard | D22: UI | E22: Risk QR-02 (isolation) | F22: QR-02, QR-01 | G22: Agent sees other agents' applications | H22: Application id owned by agent A; agent B logged in. | I22: 1. As agent B open /applications/<A's id>. 2. Open /applications/<A's id>/review and /status. | J22: SECOND_AGENT + VALID_AGENT application id | K22: Access denied (403/404 page or redirect); no data of agent A is rendered on any of the three routes. | L22: Critical | M22: P1 | N22: 2 | O22: @regression dashboard auth | P22: Screenshots + network status codes | Q22: Automated | R22: tests/dashboard/isolation.spec.ts | S22: Not run | U22: Y | V22: Negative | W22: API: GET /api/applications/{otherId} returns 403/404 | X22: Creates its own application via fixture (independent; unique generated data).
A23: TC-DASH-09 | B23: Profile and Support pages load for a logged-in agent and are protected when logged out | C23: Dashboard | D23: UI | E23: Routes /profile, /support | F23: QR-01 | G23: Support/profile route unprotected or broken | H23: Valid agent; fresh context for the logged-out part. | I23: 1. Login; open /profile and /support. 2. In a fresh context open both URLs. | J23: VALID_AGENT | K23: Both pages render for the logged-in agent; logged-out access redirects to /login. | L23: Low | M23: P3 | N23: 3 | O23: @regression dashboard auth | P23: Screenshots | Q23: Automated | R23: tests/dashboard/dashboard.spec.ts | S23: Not run | U23: N | V23: Positive | W23: - | X23: Creates its own application via fixture (independent; unique generated data).
A24: TC-CLI-01 | B24: Valid insured personal information is saved and Next is enabled | C24: Client Information | D24: UI | E24: CLI-V01 | F24: QR-03, QR-10 | G24: Valid data blocks progression | H24: Logged in; new application started. | I24: 1. Fill all mandatory client fields with valid data. 2. Click Save/Next. 3. Return to the step. | J24: Generated client (age 40) | K24: Next step becomes enabled; saved values persist when step is revisited. | L24: High | M24: P1 | N24: 1 | O24: @smoke @regression client | P24: Screenshot of filled form + revisit | Q24: Automated | R24: tests/client-information/client.spec.ts | S24: Not run | U24: Y | V24: Positive | W24: API: GET client returns saved values | X24: Creates its own application via fixture (independent; unique generated data).
A25: TC-CLI-02 | B25: Mandatory personal fields show inline errors | C25: Client Information | D25: UI | E25: CLI-V02 | F25: QR-03 | G25: Mandatory fields skipped | H25: On Client step with empty form. | I25: 1. Leave name, DOB, gender, marital status, nationality, occupation, employer blank. 2. Click Next. | J25: Empty form | K25: Each required field shows an inline error; progression blocked. Also verify: the rejected value is not saved (reload or GET shows the previous/empty value). | L25: High | M25: P1 | N25: 2 | O25: @regression client | P25: Screenshot of errors | Q25: Automated | R25: tests/client-information/client.spec.ts | S25: Not run | U25: N | V25: Negative | W25: - | X25: Creates its own application via fixture (independent; unique generated data).
A26: TC-CLI-03 | B26: DOB making client under 18 is rejected | C26: Client Information | D26: UI | E26: CLI-V03 | F26: QR-03 | G26: Age eligibility rule missed | H26: On Client step. | I26: 1. Enter DOB = today minus 18 years plus 1 day (17y 364d). 2. Attempt to proceed. | J26: DOB 17y364d | K26: Eligibility error displayed; progression blocked. Also verify: the rejected value is not saved (reload or GET shows the previous/empty value). | L26: Critical | M26: P1 | N26: 2 | O26: @regression client | P26: Screenshot of error | Q26: Automated | R26: tests/client-information/dob.spec.ts | S26: Not run | U26: Y | V26: Boundary | W26: API: POST client rejects the same DOB (see TC-API-15) | X26: Creates its own application via fixture (independent; unique generated data).
A27: TC-CLI-04 | B27: DOB making client over 65 is rejected | C27: Client Information | D27: UI | E27: CLI-V04 | F27: QR-03 | G27: Age eligibility rule missed | H27: On Client step. | I27: 1. Enter DOB = 65 years and 1 day ago. 2. Attempt to proceed. | J27: DOB 65y+1d (CONFIRM inclusivity of 65) | K27: Eligibility error displayed; progression blocked. Also verify: the rejected value is not saved (reload or GET shows the previous/empty value). | L27: Critical | M27: P1 | N27: 2 | O27: @regression client | P27: Screenshot of error | Q27: Automated | R27: tests/client-information/dob.spec.ts | S27: Not run | T27: Exact value/rule to be confirmed from app (see Open Items). | U27: Y | V27: Boundary | W27: - | X27: Creates its own application via fixture (independent; unique generated data).
A28: TC-CLI-05 | B28: Future DOB is rejected | C28: Client Information | D28: UI | E28: CLI-V05 | F28: QR-03 | G28: Future DOB accepted | H28: On Client step. | I28: 1. Enter DOB = tomorrow. 2. Attempt to proceed. | J28: DOB tomorrow | K28: Validation error shown; progression blocked. Also verify: the rejected value is not saved (reload or GET shows the previous/empty value). | L28: Critical | M28: P1 | N28: 1 | O28: @smoke @regression client | P28: Screenshot of error | Q28: Automated | R28: tests/client-information/dob.spec.ts | S28: Not run | U28: Y | V28: Boundary | W28: API: POST client rejects future DOB | X28: Creates its own application via fixture (independent; unique generated data).
A29: TC-CLI-06 | B29: Boundary ages 18 and 65 are accepted (inclusive boundary) | C29: Client Information | D29: UI | E29: Guideline: DOB rules (BVA) | F29: QR-03 | G29: Boundary off-by-one | H29: On Client step. Inclusivity of 18 and 65 confirmed (see Open Items). | I29: 1. Enter DOB exactly 18 years ago; proceed. 2. Repeat with DOB exactly 65 years ago. | J29: DOB 18y0d and 65y0d | K29: Both DOBs accepted and progression allowed (adjust if spec says 65 exclusive). Also verify: the rejected value is not saved (reload or GET shows the previous/empty value). | L29: High | M29: P2 | N29: 3 | O29: @regression client | P29: Screenshots for both boundaries | Q29: Automated | R29: tests/client-information/dob.spec.ts | S29: Not run | U29: N | V29: Boundary | W29: - | X29: Creates its own application via fixture (independent; unique generated data).
A30: TC-CLI-07 | B30: Calculated age is displayed correctly from DOB | C30: Client Information | D30: UI | E30: Guideline: age visibility | F30: QR-03 | G30: Age miscalculated | H30: On Client step. | I30: 1. Enter a DOB giving a known age (including one whose birthday is later this year). 2. Read displayed age. | J30: DOB 40y and 39y364d | K30: Displayed age equals expected age computed by test helper for each DOB. | L30: High | M30: P2 | N30: 2 | O30: @regression client | P30: Screenshot of age field | Q30: Automated | R30: tests/client-information/dob.spec.ts | S30: Not run | U30: N | V30: Positive | W30: - | X30: Creates its own application via fixture (independent; unique generated data).
A31: TC-CLI-08 | B31: Invalid name formats are rejected | C31: Client Information | D31: UI | E31: Guideline: name validation | F31: QR-03 | G31: Invalid names accepted | H31: On Client step. | I31: 1. Enter names with digits/symbols (e.g. 'J0hn#', '123', single space). 2. Attempt to proceed. | J31: 'J0hn#', '12345', ' ' | K31: Name validation error shown for each invalid value; valid name 'Anita Rao' accepted. Also verify: the rejected value is not saved (reload or GET shows the previous/empty value). | L31: Medium | M31: P2 | N31: 3 | O31: @regression client | P31: Screenshot per invalid value | Q31: Automated | R31: tests/client-information/client.spec.ts | S31: Not run | U31: N | V31: Negative | W31: - | X31: Creates its own application via fixture (independent; unique generated data).
A32: TC-CLI-09 | B32: Impossible or malformed DOB values are rejected | C32: Client Information | D32: UI | E32: Guideline: date of birth rules | F32: QR-03 | G32: Invalid DOB accepted | H32: On Client step. | I32: 1. Enter 31-Feb, 00/00/0000, text 'abc', and a year before 1900. 2. Attempt to proceed. | J32: '31-02-1990', '00-00-0000', 'abc', '01-01-1850' | K32: Each value is rejected with a date-format/range error; no age is calculated or displayed. Also verify: the rejected value is not saved (reload or GET shows the previous/empty value). | L32: Medium | M32: P2 | N32: 3 | O32: @regression client | P32: Screenshot per value | Q32: Automated | R32: tests/client-information/dob.spec.ts | S32: Not run | U32: N | V32: Boundary | W32: - | X32: Creates its own application via fixture (independent; unique generated data).
A33: TC-ADDR-01 | B33: Same-as-residential copies address to mailing | C33: Address & Contact | D33: UI | E33: CLI-V06 | F33: QR-03 | G33: Same-as-residential not copied | H33: On Address & Contact step. | I33: 1. Fill residential address. 2. Tick 'same as residential'. 3. Compare mailing fields. 4. Save and reopen. | J33: Generated address | K33: All mailing fields equal residential values; values persist after reopening. | L33: Medium | M33: P1 | N33: 1 | O33: @smoke @regression address | P33: Screenshot of copied fields | Q33: Automated | R33: tests/client-information/address.spec.ts | S33: Not run | U33: Y | V33: Positive | W33: - | X33: Creates its own application via fixture (independent; unique generated data).
A34: TC-ADDR-02 | B34: Unticking same-as-residential makes mailing editable and independent | C34: Address & Contact | D34: UI | E34: Guideline: same-as-residential | F34: QR-03 | G34: Mailing locked/overwritten | H34: Same-as-residential ticked. | I34: 1. Untick the checkbox. 2. Edit a mailing field. 3. Edit a residential field. | J34: Generated address | K34: Mailing fields become editable; editing residential no longer overwrites edited mailing values. | L34: Low | M34: P3 | N34: 3 | O34: @regression address | P34: Screenshot | Q34: Automated | R34: tests/client-information/address.spec.ts | S34: Not run | U34: N | V34: Positive | W34: - | X34: Creates its own application via fixture (independent; unique generated data).
A35: TC-ADDR-03 | B35: Invalid ZIP/postal code is rejected | C35: Address & Contact | D35: UI | E35: Guideline: ZIP validation | F35: QR-03 | G35: ZIP validation gaps | H35: On Address step. | I35: 1. Enter invalid ZIP values. 2. Attempt to proceed. | J35: 'ABCDE', '123', '1234567', blank | K35: Error shown per invalid ZIP; valid ZIP for the chosen state accepted. Also verify: the rejected value is not saved (reload or GET shows the previous/empty value). | L35: Medium | M35: P2 | N35: 2 | O35: @regression address | P35: Screenshot per value | Q35: Automated | R35: tests/client-information/address.spec.ts | S35: Not run | U35: N | V35: Negative | W35: - | X35: Creates its own application via fixture (independent; unique generated data).
A36: TC-ADDR-04 | B36: State is mandatory and ZIP/state mismatch is flagged | C36: Address & Contact | D36: UI | E36: Guideline: state validation | F36: QR-03 | G36: State validation gaps | H36: On Address step. | I36: 1. Leave state unselected; proceed. 2. Select a state and a ZIP belonging to another state (if app validates). | J36: State/ZIP pairs (CONFIRM rule) | K36: Missing state blocks progression; mismatch behavior matches confirmed rule. Also verify: the rejected value is not saved (reload or GET shows the previous/empty value). | L36: Medium | M36: P3 | N36: 3 | O36: @regression address | P36: Screenshot | Q36: Automated | R36: tests/client-information/address.spec.ts | S36: Not run | T36: Exact value/rule to be confirmed from app (see Open Items). | U36: N | V36: Negative | W36: - | X36: Creates its own application via fixture (independent; unique generated data).
A37: TC-ADDR-05 | B37: Invalid email format is rejected | C37: Address & Contact | D37: UI | E37: CLI-V07 | F37: QR-03 | G37: Email validation gap | H37: On Contact section. | I37: 1. Enter invalid emails. 2. Attempt to proceed. | J37: 'abc', 'a@b', 'a@@b.com', 'a b@c.com' | K37: Inline email error per value; valid email accepted. Also verify: the rejected value is not saved (reload or GET shows the previous/empty value). | L37: Medium | M37: P2 | N37: 2 | O37: @regression address | P37: Screenshot per value | Q37: Automated | R37: tests/client-information/contact.spec.ts | S37: Not run | U37: N | V37: Negative | W37: - | X37: Creates its own application via fixture (independent; unique generated data).
A38: TC-ADDR-06 | B38: Invalid phone number is rejected | C38: Address & Contact | D38: UI | E38: CLI-V07 | F38: QR-03 | G38: Phone validation gap | H38: On Contact section. | I38: 1. Enter invalid mobile/alternate numbers. 2. Attempt to proceed. | J38: '12345', 'abcdefghij', '+', 11-digit value (CONFIRM format) | K38: Inline phone error per value; valid number accepted. Also verify: the rejected value is not saved (reload or GET shows the previous/empty value). | L38: Medium | M38: P2 | N38: 2 | O38: @regression address | P38: Screenshot per value | Q38: Automated | R38: tests/client-information/contact.spec.ts | S38: Not run | T38: Exact value/rule to be confirmed from app (see Open Items). | U38: N | V38: Negative | W38: - | X38: Creates its own application via fixture (independent; unique generated data).
A39: TC-ADDR-07 | B39: At least one contact method / preferred mode is required | C39: Address & Contact | D39: UI | E39: Guideline: mandatory contact method | F39: QR-03 | G39: No contact method required | H39: On Contact section. | I39: 1. Clear email, mobile and alternate phone. 2. Leave preferred communication mode empty. 3. Proceed. | J39: Empty contact data | K39: Validation requires a contact method / preferred mode; progression blocked. Also verify: the rejected value is not saved (reload or GET shows the previous/empty value). | L39: Medium | M39: P2 | N39: 3 | O39: @regression address | P39: Screenshot | Q39: Automated | R39: tests/client-information/contact.spec.ts | S39: Not run | U39: N | V39: Negative | W39: - | X39: Creates its own application via fixture (independent; unique generated data).
A40: TC-KYC-01 | B40: SSN is masked after entry (only last four visible) | C40: KYC & Financial | D40: UI | E40: CLI-V08 | F40: QR-04 | G40: SSN not masked | H40: On KYC step. | I40: 1. Enter a synthetic SSN. 2. Tab away / save. 3. Reopen the step. | J40: Synthetic SSN 123-45-6789 (fake) | K40: Only last four digits visible after entry and on reopen; full value not displayed. | L40: Critical | M40: P1 | N40: 2 | O40: @regression kyc | P40: Screenshot (use fake SSN only) | Q40: Automated | R40: tests/client-information/kyc.spec.ts | S40: Not run | U40: Y | V40: Positive | W40: API/DB: stored SSN masked/encrypted (read-only) | X40: Creates its own application via fixture (independent; unique generated data).
...

Sheet Coverage Summary
A1: Coverage by Module vs Minimum Automation Coverage
A2: Minimums are from 'Submissions and Evaluations' section 5.5 (blue = hard-coded input from the source document). Counts are live formulas on the Test Cases sheet.
A4: Module | B4: Minimum Required (60-test target) | C4: Planned Test Cases | D4: Wave 1 (Smoke) | E4: P1 Cases | F4: Critical Severity | G4: Surplus / (Gap) vs Minimum | H4: Status
A5: Authentication | B5: 6 | C5: =COUNTIF('Test Cases'!$C$2:$C$174,A5) | D5: =COUNTIFS('Test Cases'!$C$2:$C$174,A5,'Test Cases'!$N$2:$N$174,1) | E5: =COUNTIFS('Test Cases'!$C$2:$C$174,A5,'Test Cases'!$M$2:$M$174,"P1") | F5: =COUNTIFS('Test Cases'!$C$2:$C$174,A5,'Test Cases'!$L$2:$L$174,"Critical") | G5: =C5-B5 | H5: =IF(C5>=B5,"Meets minimum","GAP")
A6: Dashboard | B6: 4 | C6: =COUNTIF('Test Cases'!$C$2:$C$174,A6) | D6: =COUNTIFS('Test Cases'!$C$2:$C$174,A6,'Test Cases'!$N$2:$N$174,1) | E6: =COUNTIFS('Test Cases'!$C$2:$C$174,A6,'Test Cases'!$M$2:$M$174,"P1") | F6: =COUNTIFS('Test Cases'!$C$2:$C$174,A6,'Test Cases'!$L$2:$L$174,"Critical") | G6: =C6-B6 | H6: =IF(C6>=B6,"Meets minimum","GAP")
A7: Client Information | B7: 8 | C7: =COUNTIF('Test Cases'!$C$2:$C$174,A7) | D7: =COUNTIFS('Test Cases'!$C$2:$C$174,A7,'Test Cases'!$N$2:$N$174,1) | E7: =COUNTIFS('Test Cases'!$C$2:$C$174,A7,'Test Cases'!$M$2:$M$174,"P1") | F7: =COUNTIFS('Test Cases'!$C$2:$C$174,A7,'Test Cases'!$L$2:$L$174,"Critical") | G7: =C7-B7 | H7: =IF(C7>=B7,"Meets minimum","GAP")
A8: Address & Contact | B8: 5 | C8: =COUNTIF('Test Cases'!$C$2:$C$174,A8) | D8: =COUNTIFS('Test Cases'!$C$2:$C$174,A8,'Test Cases'!$N$2:$N$174,1) | E8: =COUNTIFS('Test Cases'!$C$2:$C$174,A8,'Test Cases'!$M$2:$M$174,"P1") | F8: =COUNTIFS('Test Cases'!$C$2:$C$174,A8,'Test Cases'!$L$2:$L$174,"Critical") | G8: =C8-B8 | H8: =IF(C8>=B8,"Meets minimum","GAP")
A9: KYC & Financial | B9: 6 | C9: =COUNTIF('Test Cases'!$C$2:$C$174,A9) | D9: =COUNTIFS('Test Cases'!$C$2:$C$174,A9,'Test Cases'!$N$2:$N$174,1) | E9: =COUNTIFS('Test Cases'!$C$2:$C$174,A9,'Test Cases'!$M$2:$M$174,"P1") | F9: =COUNTIFS('Test Cases'!$C$2:$C$174,A9,'Test Cases'!$L$2:$L$174,"Critical") | G9: =C9-B9 | H9: =IF(C9>=B9,"Meets minimum","GAP")
A10: Product & Policy | B10: 6 | C10: =COUNTIF('Test Cases'!$C$2:$C$174,A10) | D10: =COUNTIFS('Test Cases'!$C$2:$C$174,A10,'Test Cases'!$N$2:$N$174,1) | E10: =COUNTIFS('Test Cases'!$C$2:$C$174,A10,'Test Cases'!$M$2:$M$174,"P1") | F10: =COUNTIFS('Test Cases'!$C$2:$C$174,A10,'Test Cases'!$L$2:$L$174,"Critical") | G10: =C10-B10 | H10: =IF(C10>=B10,"Meets minimum","GAP")
A11: Riders | B11: 5 | C11: =COUNTIF('Test Cases'!$C$2:$C$174,A11) | D11: =COUNTIFS('Test Cases'!$C$2:$C$174,A11,'Test Cases'!$N$2:$N$174,1) | E11: =COUNTIFS('Test Cases'!$C$2:$C$174,A11,'Test Cases'!$M$2:$M$174,"P1") | F11: =COUNTIFS('Test Cases'!$C$2:$C$174,A11,'Test Cases'!$L$2:$L$174,"Critical") | G11: =C11-B11 | H11: =IF(C11>=B11,"Meets minimum","GAP")
A12: Beneficiaries | B12: 7 | C12: =COUNTIF('Test Cases'!$C$2:$C$174,A12) | D12: =COUNTIFS('Test Cases'!$C$2:$C$174,A12,'Test Cases'!$N$2:$N$174,1) | E12: =COUNTIFS('Test Cases'!$C$2:$C$174,A12,'Test Cases'!$M$2:$M$174,"P1") | F12: =COUNTIFS('Test Cases'!$C$2:$C$174,A12,'Test Cases'!$L$2:$L$174,"Critical") | G12: =C12-B12 | H12: =IF(C12>=B12,"Meets minimum","GAP")
A13: Documents & Validation | B13: 4 | C13: =COUNTIF('Test Cases'!$C$2:$C$174,A13) | D13: =COUNTIFS('Test Cases'!$C$2:$C$174,A13,'Test Cases'!$N$2:$N$174,1) | E13: =COUNTIFS('Test Cases'!$C$2:$C$174,A13,'Test Cases'!$M$2:$M$174,"P1") | F13: =COUNTIFS('Test Cases'!$C$2:$C$174,A13,'Test Cases'!$L$2:$L$174,"Critical") | G13: =C13-B13 | H13: =IF(C13>=B13,"Meets minimum","GAP")
A14: Submission & Status | B14: 5 | C14: =COUNTIF('Test Cases'!$C$2:$C$174,A14) | D14: =COUNTIFS('Test Cases'!$C$2:$C$174,A14,'Test Cases'!$N$2:$N$174,1) | E14: =COUNTIFS('Test Cases'!$C$2:$C$174,A14,'Test Cases'!$M$2:$M$174,"P1") | F14: =COUNTIFS('Test Cases'!$C$2:$C$174,A14,'Test Cases'!$L$2:$L$174,"Critical") | G14: =C14-B14 | H14: =IF(C14>=B14,"Meets minimum","GAP")
A15: API | B15: 8 | C15: =COUNTIF('Test Cases'!$C$2:$C$174,A15) | D15: =COUNTIFS('Test Cases'!$C$2:$C$174,A15,'Test Cases'!$N$2:$N$174,1) | E15: =COUNTIFS('Test Cases'!$C$2:$C$174,A15,'Test Cases'!$M$2:$M$174,"P1") | F15: =COUNTIFS('Test Cases'!$C$2:$C$174,A15,'Test Cases'!$L$2:$L$174,"Critical") | G15: =C15-B15 | H15: =IF(C15>=B15,"Meets minimum","GAP")
A16: Cross-Cutting | B16: 0 | C16: =COUNTIF('Test Cases'!$C$2:$C$174,A16) | D16: =COUNTIFS('Test Cases'!$C$2:$C$174,A16,'Test Cases'!$N$2:$N$174,1) | E16: =COUNTIFS('Test Cases'!$C$2:$C$174,A16,'Test Cases'!$M$2:$M$174,"P1") | F16: =COUNTIFS('Test Cases'!$C$2:$C$174,A16,'Test Cases'!$L$2:$L$174,"Critical") | G16: =C16-B16 | H16: =IF(C16>=B16,"Meets minimum","GAP")
A17: TOTAL | B17: =SUM(B5:B16) | C17: =SUM(C5:C16) | D17: =SUM(D5:D16) | E17: =SUM(E5:E16) | F17: =SUM(F5:F16) | G17: =SUM(G5:G16) | H17: =IF(C17>=B17,"Meets 60","Below 60")
A19: Reduced-scope option
A20: Short-cohort set (30-35 tests): Wave 1 + all Critical cases + 5 extras (lockout, rider rules, premium) so auth, one E2E, allocation, rider rules, API and reporting stay covered. Count flagged 'Y': | D20: =COUNTIF('Test Cases'!$U$2:$U$174,"Y")
A21: Wave 1 (smoke) cases: | D21: =COUNTIF('Test Cases'!$N$2:$N$174,1)
A23: Automation progress
A24: Not started | D24: =COUNTIF('Test Cases'!$Q$2:$Q$174,A24)
A25: In progress | D25: =COUNTIF('Test Cases'!$Q$2:$Q$174,A25)
A26: Automated | D26: =COUNTIF('Test Cases'!$Q$2:$Q$174,A26)
A27: Manual only | D27: =COUNTIF('Test Cases'!$Q$2:$Q$174,A27)
A28: Blocked | D28: =COUNTIF('Test Cases'!$Q$2:$Q$174,A28)
A29: Not applicable | D29: =COUNTIF('Test Cases'!$Q$2:$Q$174,A29)
A31: Test type split
A32: UI | D32: =COUNTIF('Test Cases'!$D$2:$D$174,A32)
A33: API | D33: =COUNTIF('Test Cases'!$D$2:$D$174,A33)
A34: E2E | D34: =COUNTIF('Test Cases'!$D$2:$D$174,A34)
A36: Scenario mix (guards against happy-path-only suites)
A37: Positive | D37: =COUNTIF('Test Cases'!$V$2:$V$174,A37) | E37: =D37/SUM($D$37:$D$39)
A38: Negative | D38: =COUNTIF('Test Cases'!$V$2:$V$174,A38) | E38: =D38/SUM($D$37:$D$39)
A39: Boundary | D39: =COUNTIF('Test Cases'!$V$2:$V$174,A39) | E39: =D39/SUM($D$37:$D$39)
A40: Negative + Boundary share (target: at least 50%) | D40: =(D38+D39)/SUM(D37:D39)

Sheet Risk Traceability
A1: Traceability: Submission 1 Risk Register (QR-01..QR-14) to Test Cases
A3: Risk ID | B3: Area | C3: Risk (from Submission 1) | D3: Priority | E3: # Test Cases | F3: Coverage
A4: QR-01 | B4: Authentication | C4: Unauthorized protected-route or API access | D4: Critical | E4: =COUNTIF('Test Cases'!$F$2:$F$174,"*"&A4&"*") | F4: =IF(E4>0,"Covered by test cases",IF(OR(A4="QR-11",A4="QR-12",A4="QR-13",A4="QR-14"),"Covered by framework/config","GAP"))
A5: QR-02 | B5: Dashboard | C5: Cross-agent data exposure or incorrect status | D5: Critical | E5: =COUNTIF('Test Cases'!$F$2:$F$174,"*"&A5&"*") | F5: =IF(E5>0,"Covered by test cases",IF(OR(A5="QR-11",A5="QR-12",A5="QR-13",A5="QR-14"),"Covered by framework/config","GAP"))
A6: QR-03 | B6: Client | C6: DOB boundary or age calculation failure | D6: Critical | E6: =COUNTIF('Test Cases'!$F$2:$F$174,"*"&A6&"*") | F6: =IF(E6>0,"Covered by test cases",IF(OR(A6="QR-11",A6="QR-12",A6="QR-13",A6="QR-14"),"Covered by framework/config","GAP"))
A7: QR-04 | B7: KYC/Compliance | C7: Sensitive ID exposure or mandatory evidence bypass | D7: Critical | E7: =COUNTIF('Test Cases'!$F$2:$F$174,"*"&A7&"*") | F7: =IF(E7>0,"Covered by test cases",IF(OR(A7="QR-11",A7="QR-12",A7="QR-13",A7="QR-14"),"Covered by framework/config","GAP"))
A8: QR-05 | B8: Product/Premium | C8: Invalid configuration or inconsistent premium | D8: Critical | E8: =COUNTIF('Test Cases'!$F$2:$F$174,"*"&A8&"*") | F8: =IF(E8>0,"Covered by test cases",IF(OR(A8="QR-11",A8="QR-12",A8="QR-13",A8="QR-14"),"Covered by framework/config","GAP"))
A9: QR-06 | B9: Riders | C9: Eligibility, coverage, count or exclusion rule bypass | D9: Critical | E9: =COUNTIF('Test Cases'!$F$2:$F$174,"*"&A9&"*") | F9: =IF(E9>0,"Covered by test cases",IF(OR(A9="QR-11",A9="QR-12",A9="QR-13",A9="QR-14"),"Covered by framework/config","GAP"))
A10: QR-07 | B10: Beneficiaries | C10: Invalid allocation, duplicate or missing guardian accepted | D10: Critical | E10: =COUNTIF('Test Cases'!$F$2:$F$174,"*"&A10&"*") | F10: =IF(E10>0,"Covered by test cases",IF(OR(A10="QR-11",A10="QR-12",A10="QR-13",A10="QR-14"),"Covered by framework/config","GAP"))
A11: QR-08 | B11: Documents/Review | C11: Invalid upload or stale validation summary | D11: High | E11: =COUNTIF('Test Cases'!$F$2:$F$174,"*"&A11&"*") | F11: =IF(E11>0,"Covered by test cases",IF(OR(A11="QR-11",A11="QR-12",A11="QR-13",A11="QR-14"),"Covered by framework/config","GAP"))
A12: QR-09 | B12: Submission | C12: Incomplete case submits or reference/state is wrong | D12: Critical | E12: =COUNTIF('Test Cases'!$F$2:$F$174,"*"&A12&"*") | F12: =IF(E12>0,"Covered by test cases",IF(OR(A12="QR-11",A12="QR-12",A12="QR-13",A12="QR-14"),"Covered by framework/config","GAP"))
A13: QR-10 | B13: Persistence | C13: Draft or submitted values not saved accurately | D13: High | E13: =COUNTIF('Test Cases'!$F$2:$F$174,"*"&A13&"*") | F13: =IF(E13>0,"Covered by test cases",IF(OR(A13="QR-11",A13="QR-12",A13="QR-13",A13="QR-14"),"Covered by framework/config","GAP"))
A14: QR-11 | B14: Automation | C14: Flaky checks or weak evidence hides true result | D14: Medium | E14: =COUNTIF('Test Cases'!$F$2:$F$174,"*"&A14&"*") | F14: =IF(E14>0,"Covered by test cases",IF(OR(A14="QR-11",A14="QR-12",A14="QR-13",A14="QR-14"),"Covered by framework/config","GAP"))
A15: QR-12 | B15: Test Data | C15: Seed collision or reset changes expected state | D15: High | E15: =COUNTIF('Test Cases'!$F$2:$F$174,"*"&A15&"*") | F15: =IF(E15>0,"Covered by test cases",IF(OR(A15="QR-11",A15="QR-12",A15="QR-13",A15="QR-14"),"Covered by framework/config","GAP"))
... A17: QR-14 | B17: Environment | C17: Shared service or dependency prevents valid testing | D17: High | E17: =COUNTIF('Test Cases'!$F$2:$F$174,"*"&A17&"*") | F17: =IF(E17>0,"Covered by test cases",IF(OR(A17="QR-11",A17="QR-12",A17="QR-13",A17="QR-14"),"Covered by framework/config","GAP"))
A19: QR-11 to QR-14 are addressed by framework design, not individual test cases: stable locators and trace/screenshot config (QR-11), unique generated data per run plus reserved seed users (QR-12), the Chromium/Firefox/WebKit projects in playwright.config.ts (QR-13), and a health-check / global-setup step (QR-14). They are documented in the README.

Sheet Validation ID Matrix
A1: Every Validation ID in the problem statement mapped to a test case
A3: Validation ID | B3: Scenario (from Functional Module Descriptions) | C3: Mapped Test Case(s) | D3: # Mapped | E3: Status
A4: AUTH-V01 | B4: Valid agent can log in successfully | C4: TC-AUTH-01 | D4: =COUNTIF('Test Cases'!$E$2:$E$174,"*"&A4&"*") | E4: =IF(D4>0,"Covered","GAP")
A5: AUTH-V02 | B5: Invalid password displays correct error message | C5: TC-AUTH-02 | D5: =COUNTIF('Test Cases'!$E$2:$E$174,"*"&A5&"*") | E5: =IF(D5>0,"Covered","GAP")
A6: AUTH-V03 | B6: Blank username and password show mandatory validation | C6: TC-AUTH-03 | D6: =COUNTIF('Test Cases'!$E$2:$E$174,"*"&A6&"*") | E6: =IF(D6>0,"Covered","GAP")
A7: AUTH-V04 | B7: Logout clears session and redirects to login page | C7: TC-AUTH-04 | D7: =COUNTIF('Test Cases'!$E$2:$E$174,"*"&A7&"*") | E7: =IF(D7>0,"Covered","GAP")
A8: AUTH-V05 | B8: Direct access to dashboard without login is blocked | C8: TC-AUTH-05 | D8: =COUNTIF('Test Cases'!$E$2:$E$174,"*"&A8&"*") | E8: =IF(D8>0,"Covered","GAP")
A9: AUTH-V06 | B9: Locked user cannot access dashboard | C9: TC-AUTH-06 | D9: =COUNTIF('Test Cases'!$E$2:$E$174,"*"&A9&"*") | E9: =IF(D9>0,"Covered","GAP")
A10: AUTH-V07 | B10: Account locks after five failed login attempts | C10: TC-AUTH-07 | D10: =COUNTIF('Test Cases'!$E$2:$E$174,"*"&A10&"*") | E10: =IF(D10>0,"Covered","GAP")
A11: AUTH-V08 | B11: Password policy rejects weak password | C11: TC-AUTH-08 | D11: =COUNTIF('Test Cases'!$E$2:$E$174,"*"&A11&"*") | E11: =IF(D11>0,"Covered","GAP")
A12: DASH-V01 | B12: Dashboard loads after successful login | C12: TC-DASH-01 | D12: =COUNTIF('Test Cases'!$E$2:$E$174,"*"&A12&"*") | E12: =IF(D12>0,"Covered","GAP")
A13: DASH-V02 | B13: Agent sees only own applications | C13: TC-DASH-02 | D13: =COUNTIF('Test Cases'!$E$2:$E$174,"*"&A13&"*") | E13: =IF(D13>0,"Covered","GAP")
A14: DASH-V03 | B14: New agent sees empty application state | C14: TC-DASH-03 | D14: =COUNTIF('Test Cases'!$E$2:$E$174,"*"&A14&"*") | E14: =IF(D14>0,"Covered","GAP")
A15: DASH-V04 | B15: Draft application can be resumed | C15: TC-DASH-04 | D15: =COUNTIF('Test Cases'!$E$2:$E$174,"*"&A15&"*") | E15: =IF(D15>0,"Covered","GAP")
... A72: API-V08 | B72: Applications API returns only logged-in agent records | C72: TC-API-08 | D72: =COUNTIF('Test Cases'!$E$2:$E$174,"*"&A72&"*") | E72: =IF(D72>0,"Covered","GAP")
B74: Validation IDs without a test case: | D74: =COUNTIF(E4:E72,"GAP")

Sheet Test Data
A1: Controlled Test Data (generated per run; never hard-code in specs)
A2: Boundary DOBs are formulas relative to today so the sheet always shows the dates for the day you read it. dataGenerator.ts must compute the same values at run time.
A4: Dataset | B4: Date of Birth (calculated) | C4: Expected Outcome | D4: Used By
A5: Underage - 17 years 364 days | B5: =EDATE(TODAY(),-216)+1 | C5: Rejected (below 18) | D5: TC-CLI-03, TC-API-03, TC-BEN-05 (as minor)
A6: Exactly 18 years | B6: =EDATE(TODAY(),-216) | C6: Accepted (confirm inclusive) | D6: TC-CLI-06
A7: Typical adult - 40 years | B7: =EDATE(TODAY(),-480) | C7: Accepted | D7: TC-CLI-01, TC-WF-03
A8: Exactly 65 years | B8: =EDATE(TODAY(),-780) | C8: Accepted (confirm inclusive) | D8: TC-CLI-06
A9: Over 65 - 65 years + 1 day | B9: =EDATE(TODAY(),-780)-1 | C9: Rejected (above 65) | D9: TC-CLI-04
A10: Future date - tomorrow | B10: =TODAY()+1 | C10: Rejected | D10: TC-CLI-05, TC-API-03
A12: Allocation datasets
A13: Scenario | B13: Primary % | C13: Secondary % | D13: Expected
A14: Exact | B14: 100 | C14: 100 | D14: Accepted
A15: Under | B15: 99 | C15: - | D15: Blocked
A16: Over | B16: 101 | C16: - | D16: Blocked
A17: Split 60/40 | B17: 60 + 40 | C17: - | D17: Accepted; removing 40 leaves 60 -> error
A18: Secondary short | B18: 100 | C18: 90 | D18: Blocked (secondary total)
A21: Upload files (fixtures/files)
A22: File | B22: Type / Size | C22: Expected | D22: Used By
A23: valid.pdf | B23: PDF, ~50 KB | C23: Accepted | D23: TC-DOC-01
A24: valid.jpg | B24: JPG, ~50 KB | C24: Accepted | D24: TC-DOC-01
A25: valid.png | B25: PNG, ~50 KB | C25: Accepted | D25: TC-DOC-01
A26: invalid.exe | B26: EXE (renamed dummy) | C26: Rejected - type | D26: TC-KYC-03, TC-DOC-02
A27: invalid.txt | B27: TXT | C27: Rejected - type | D27: TC-KYC-03, TC-DOC-02
A28: under-limit.pdf | B28: max size - 1 byte (CONFIRM max) | C28: Accepted | D28: TC-DOC-03
A29: over-limit.pdf | B29: max size + 1 byte (CONFIRM max) | C29: Rejected - size | D29: TC-DOC-03
A32: Environment variables (.env.example placeholders - no real values)
A33: Variable | B33: Purpose | C33: Placeholder
A34: BASE_URL | B34: App base URL | C34: http://127.0.0.1:8081
A35: APP_NAME | B35: insurance or finserve | C35: insurance
A36: VALID_AGENT_USER / _PASS | B36: Happy path agent | C36: <from seed data doc>
A37: SECOND_AGENT_USER / _PASS | B37: Data isolation | C37: <from seed data doc>
A38: NEW_AGENT_USER / _PASS | B38: Empty dashboard | C38: <from seed data doc>
A39: LOCKED_AGENT_USER / _PASS | B39: Locked message | C39: <from seed data doc>
A40: LOCKOUT_TEST_AGENT_USER / _PASS | B40: Reserved for 5-attempt lock test | C40: <from seed data doc>
A41: MFA_AGENT_USER / _PASS / MFA_OTP | B41: OTP login | C41: <from seed data doc>
A42: API_BASE_URL | B42: API root | C42: ${BASE_URL}/api
A43: SEEDED_DRAFT_ID / SEEDED_SUBMITTED_ID | B43: Resume and read-only checks | C43: <from seed data doc>

Sheet Open Items
A1: Values to confirm from the running app / mentor before asserting exact results
A3: # | B3: Item to confirm | C3: Why it matters | D3: Affected Test Cases | E3: Resolution (fill in) | F3: Status
A4: 1 | B4: Insurance app port (8081 vs 8082) and base URL | C4: FinServe app also runs in the lab | D4: All | F4: Open
A5: 2 | B5: Seed users, passwords, MFA OTP value, lockout reset method | C5: Auth and isolation tests | D5: TC-AUTH-*, TC-DASH-02/03, TC-API-08 | F5: Open
A6: 3 | B6: Are ages 18 and 65 inclusive? Timezone for age calculation? | C6: Boundary assertions | D6: TC-CLI-03/04/06 | F6: Open
A7: 4 | B7: Password policy and failed-attempt/lock-reset rules | C7: Exact weak-password set | D7: TC-AUTH-07/08/11 | F7: Open
A8: 5 | B8: Product face value min/max, payment and policy terms, active vs inactive products | C8: Boundary values | D8: TC-PROD-* | F8: Open
A9: 6 | B9: Premium formula/rounding or API field exposing premium | C9: Recalculation assertions | D9: TC-PROD-05/06, TC-RID-07 | F9: Open
A10: 7 | B10: Rider age limits, max rider count, coverage caps, waiver pair | C10: Rider decision table | D10: TC-RID-* | F10: Open
A11: 8 | B11: ID types and number formats; SSN mask format | C11: KYC validation | D11: TC-KYC-01/02/07 | F11: Open
A12: 9 | B12: Affordability rule (income vs premium) | C12: Warning vs block | D12: TC-KYC-05 | F12: Open
A13: 10 | B13: Allowed file types, max file size, mandatory documents by scenario | C13: Upload tests | D13: TC-KYC-03, TC-DOC-* | F13: Open
A14: 11 | B14: Duplicate beneficiary exact key and irrevocable modal wording | C14: Duplicate/special tests | D14: TC-BEN-08/10 | F14: Open
A15: 12 | B15: Seeded defect catalog / defect codes | C15: Replace descriptive defect links with codes | D15: All (column G) | F15: Open
... A23: 20 | B23: Dashboard and catalog search fields (name, reference, product) | C23: Search assertions | D23: TC-DASH-07, TC-PROD-13 | F23: Open

Sheet Review Log
A1: Reviewer Findings and Changes Applied (v2 review against Submission 2 documents)
A3: # | B3: Type | C3: Finding | D3: Source requirement | E3: Action taken | F3: Test case(s)
A4: 1 | B4: Gap | C4: No test for session timeout / expiry | D4: Auth automation focus: session timeout; Sub 1 path 'Session expiration' | E4: Added session-expiry test | F4: TC-AUTH-12
A5: 2 | B5: Gap | C5: Pending (unapproved) agent role not tested | D5: Auth user types; Sub 1 roles table | E5: Added pending-agent access test | F5: TC-AUTH-13
A6: 3 | B6: Gap | C6: Dashboard search and profile/support routes not covered | D6: Dashboard: search, filters; routes /profile, /support | E6: Added search and route tests | F6: TC-DASH-07, TC-DASH-09
A7: 4 | B7: Gap | C7: Cross-agent access only tested via lists, not direct URL | D7: Risk QR-02 (Critical) | E7: Added direct-URL isolation test | F7: TC-DASH-08
A8: 5 | B8: Gap | C8: Impossible/malformed DOB values not tested | D8: Client DOB boundaries, date validation | E8: Added malformed DOB test | F8: TC-CLI-09
A9: 6 | B9: Gap | C9: Financial suitability fields (income, net worth, source of funds, risk profile) and ID expiry not validated | D9: KYC and financial spec | E9: Added two KYC tests | F9: TC-KYC-08, TC-KYC-09
A10: 7 | B10: Gap | C10: Product eligibility vs client age was missing although listed in problem statement 2.2 | D10: Problem statement 2.2 | E10: Added eligibility test (High, P1) | F10: TC-PROD-10
A11: 8 | B11: Gap | C11: Payment/policy term rules, invalid face-value inputs, catalog search and UI-vs-API premium not covered | D11: Product spec table; ProductCatalogPage; premium API reconciliation | E11: Added four product tests | F11: TC-PROD-11..14
A12: 9 | B12: Gap | C12: Rider dependency rules and rider removal not covered | D12: Rider spec: dependency rules; premium itemization | E12: Added two rider tests | F12: TC-RID-08, TC-RID-09
A13: 10 | B13: Gap | C13: Beneficiary edit, invalid allocation inputs and persistence not covered | D13: Beneficiary spec: add/edit/remove; allocation; persistence | E13: Added three beneficiary tests | F13: TC-BEN-12..14
A14: 11 | B14: Gap | C14: Validation summary staleness was bundled inside the submit-gating test; review data consistency and upload persistence missing | D14: Guideline: review consistency; Risk QR-08 | E14: Split stale-summary into its own test; added review-consistency and upload-persistence tests | F14: TC-VAL-03/04/05, TC-DOC-05
A15: 12 | B15: Gap | C15: No smoke path that stops at review (guideline build step 5); no double-submit, confirmation gating or submitted-data persistence tests | D15: Guideline 4 step 5; Risk QR-09, QR-10 | E15: Added four workflow tests | F15: TC-WF-10..13
... A28: 25 | B28: Quality | C28: Short-cohort fallback was a loose rule | D28: Min coverage 30-35 option | E28: Defined an explicit flagged set that keeps auth, E2E, allocation, rider rules, API | F28: Short-Cohort Set = Y
